<?xml version="1.0"?>
<robot name="ghost_15" xmlns:xacro="http://ros.org/wiki/xacro">

    <xacro:include filename="$(find ghost_swerve)/urdf/swerve_v2_macros.xacro"/>

    <xacro:property name="r_wheel" value="0.034925"/> 
    <xacro:property name="width_wheel" value="0.0254"/> 
    <xacro:property name="com_radius" value="0.02"/>
    <xacro:property name="d2r" value="${3.14159/180}"/>

    <link name="base_link">
        <visual>
        <origin xyz="0 0 0" rpy="0 0 0"/>
        <geometry>
            <box size="0 0 0"/>
        </geometry>
            <material name="silver">
                <color rgba="0.9 0.9 0.9 1.0"/>
            </material>
        </visual>

        <!--Inertia estimated for solid cylinder of radius 9" and height 3" with mass 7kg-->
        <inertial>
            <origin xyz="0 0 0" rpy="0 0 0"/>
            <mass value="10"/>
            <inertia
                ixx="0.094839" ixy="0.0" ixz="0.0"
                iyy="0.094839" iyz="0.0"
                izz="0.182903"/>
        </inertial>

        <gazebo>
            <maxVel>3.0</maxVel>
        </gazebo>
    </link>


    <link name="front_bar">
        <visual>
        <origin xyz="0 0 0" rpy="0 0 0"/>
        <geometry>
            <box size="0.0127 0.3302 0.0254"/>
        </geometry>
            <material name="silver">
                <color rgba="0.9 0.9 0.9 1.0"/>
            </material>
        </visual>
    </link>    

    <joint name="front_bar_joint" type="fixed">
        <parent link="base_link"/>
        <child link="front_bar"/>
        <origin xyz="-0.15875 0 0" rpy="0 0 0"/>
        <axis xyz="0 0 1"/>
    </joint>

     <link name="back_bar">
        <visual>
        <origin xyz="0 0 0" rpy="0 0 0"/>
        <geometry>
            <box size="0.0127 0.3302 0.0254"/>
        </geometry>
            <material name="silver">
                <color rgba="0.9 0.9 0.9 1.0"/>
            </material>
        </visual>
    </link>    

    <joint name="back_bar_joint" type="fixed">
        <parent link="base_link"/>
        <child link="back_bar"/>
        <origin xyz="0.15875 0 0" rpy="0 0 0"/>
        <axis xyz="0 0 1"/>
    </joint>

    <link name="left_bar">
        <visual>
        <origin xyz="0 0 0" rpy="0 0 0"/>
        <geometry>
            <box size="0.0127 0.3048 0.0254"/>
        </geometry>
            <material name="silver">
                <color rgba="0.9 0.9 0.9 1.0"/>
            </material>
        </visual>
    </link>

    <joint name="left_bar_joint" type="fixed">
        <parent link="base_link"/>
        <child link="left_bar"/>
        <origin xyz="0 0.15875 0" rpy="0 0 1.5708"/>
        <axis xyz="0 0 1"/>
    </joint>

    <link name="right_bar">
        <visual>
        <origin xyz="0 0 0" rpy="0 0 0"/>
        <geometry>
            <box size="0.0127 0.3048 0.0254"/>
        </geometry>
            <material name="silver">
                <color rgba="0.9 0.9 0.9 1.0"/>
            </material>
    </visual>
    </link>

    <joint name="right_bar_joint" type="fixed">
        <parent link="base_link"/>
        <child link="right_bar"/>
        <origin xyz="0 -0.15875 0" rpy="0 0 1.5708"/>
        <axis xyz="0 0 1"/>
    </joint>

    <!-- Steering Modules -->
    <xacro:steering_macro id="frontleft"></xacro:steering_macro>
    <xacro:steering_macro id="frontright"></xacro:steering_macro>
    <xacro:steering_macro id="backleft"></xacro:steering_macro>
    <xacro:steering_macro id="backright"></xacro:steering_macro>

    <!-- Wheel Modules -->
    <xacro:wheel_macro id="frontleft" r_wheel="${r_wheel}" width_wheel="${width_wheel}" collision_factor="8"></xacro:wheel_macro>
    <xacro:wheel_macro id="frontright" r_wheel="${r_wheel}" width_wheel="${width_wheel}" collision_factor="8"></xacro:wheel_macro>
    <xacro:wheel_macro id="backleft" r_wheel="${r_wheel}" width_wheel="${width_wheel}" collision_factor="8"></xacro:wheel_macro>
    <xacro:wheel_macro id="backright" r_wheel="${r_wheel}" width_wheel="${width_wheel}" collision_factor="8"></xacro:wheel_macro>
    <!-- Joints -->
    <joint name="steering_joint_backleft" type="continuous">
        <parent link="base_link"/>
        <child link="steering_link_backleft"/>
        <origin xyz="-0.1143 0.1143 0.0762" rpy="0 0 0"/> 
        <dynamics damping="0.0" friction="0.0"/>
        <axis xyz="0 0 1"/>
    </joint>

    <joint name="steering_joint_backright" type="continuous">
        <parent link="base_link"/>
        <child link="steering_link_backright"/>
        <origin xyz="0.1143 0.1143 0.0762" rpy="0 0 0"/>
        <dynamics damping="0.0" friction="0.0"/>
        <axis xyz="0 0 1"/>
    </joint>

    <joint name="steering_joint_frontleft" type="continuous">
        <parent link="base_link"/>
        <child link="steering_link_frontleft"/>
        <origin xyz="-0.1143 -0.1143 0.0762" rpy="0 0 0"/>
        <dynamics damping="0.0" friction="0.0"/>
        <axis xyz="0 0 1"/>
    </joint>

    <joint name="steering_joint_frontright" type="continuous">
        <parent link="base_link"/>
        <child link="steering_link_frontright"/>
        <origin xyz="0.1143 -0.1143 0.0762 " rpy="0 0 0"/> 
        <dynamics damping="0.0" friction="0.0"/>
        <axis xyz="0 0 1"/>
    </joint>

    <joint name="wheel_joint_backleft" type="continuous">
        <parent link="steering_link_backleft"/>
        <child link="wheel_link_backleft"/>
        <origin xyz="0 0 -0.09886" rpy="${90*d2r} 0 0"/> 
        <dynamics damping="0.0" friction="0.0"/>
        <axis xyz="0 0 1"/>
    </joint>

    <joint name="wheel_joint_backright" type="continuous">
        <parent link="steering_link_backright"/>
        <child link="wheel_link_backright"/>
        <origin xyz="0 0 -0.09886" rpy="${90*d2r} 0 0"/>
        <dynamics damping="0.0" friction="0.0"/>
        <axis xyz="0 0 1"/>
    </joint>

    <joint name="wheel_joint_frontleft" type="continuous">
        <parent link="steering_link_frontleft"/>
        <child link="wheel_link_frontleft"/>
        <origin xyz="0 0 -0.09886" rpy="${90*d2r} 0 0"/>
        <dynamics damping="0.0" friction="0.0"/>
        <axis xyz="0 0 1"/>
    </joint>

    <joint name="wheel_joint_frontright" type="continuous">
        <parent link="steering_link_frontright"/>
        <child link="wheel_link_frontright"/>
        <origin xyz="0 0 -0.09886" rpy="${90*d2r} 0 0"/>
        <dynamics damping="0.0" friction="0.0"/>
        <axis xyz="0 0 1"/>
    </joint>

    <!-- Gears :) 
     <link name="gear_backleft">
        <visual>
        <origin xyz="0 0 0" rpy="0 0 0"/>
        <geometry>
           <cylinder radius="0.04826" length="0.0127"/>
        </geometry>
            <material name="orange">
                <color rgba="1.0 0.5 0.0 1.0"/>
            </material>
        </visual>
    </link>

     <joint name="steering_gear_backleft" type="continuous">
        <parent link="steering_link_backleft"/>
        <child link="gear_backleft"/>
        <origin xyz="0 0 -0.0508" rpy="0 0 0"/> 
        <dynamics damping="0.0" friction="0.0"/>
        <axis xyz="0 0 1"/>
    </joint>

    

     <link name="gear_backright">
        <visual>
        <origin xyz="0 0 0" rpy="0 0 0"/>
        <geometry>
           <cylinder radius="0.04826" length="0.0127"/>
        </geometry>
            <material name="orange">
                <color rgba="1.0 0.5 0.0 1.0"/>
            </material>
        </visual>
    </link>

     <joint name="steering_gear_backright" type="continuous">
        <parent link="steering_link_backright"/>
        <child link="gear_backright"/>
        <origin xyz="0 0 -0.0508" rpy="0 0 0"/> 
        <dynamics damping="0.0" friction="0.0"/>
        <axis xyz="0 0 1"/>
    </joint>

     <link name="gear_frontleft">
        <visual>
        <origin xyz="0 0 0" rpy="0 0 0"/>
        <geometry>
           <cylinder radius="0.04826" length="0.0127"/>
        </geometry>
            <material name="orange">
                <color rgba="1.0 0.5 0.0 1.0"/>
            </material>
        </visual>
    </link>

     <joint name="steering_gear_frontleft" type="continuous">
        <parent link="steering_link_frontleft"/>
        <child link="gear_frontleft"/>
        <origin xyz="0 0 -0.0508" rpy="0 0 0"/> 
        <dynamics damping="0.0" friction="0.0"/>
        <axis xyz="0 0 1"/>
    </joint>

<link name="gear_frontright">
        <visual>
        <origin xyz="0 0 0" rpy="0 0 0"/>
        <geometry>
           <cylinder radius="0.04826" length="0.0127"/>
        </geometry>
            <material name="orange">
                <color rgba="1.0 0.5 0.0 1.0"/>
            </material>
        </visual>
    </link>

     <joint name="steering_gear_frontright" type="continuous">
        <parent link="steering_link_frontright"/>
        <child link="gear_frontright"/>
        <origin xyz="0 0 -0.0508" rpy="0 0 0"/> 
        <dynamics damping="0.0" friction="0.0"/>
        <axis xyz="0 0 1"/>
    </joint>-->


    <!-- Sensors -->
    <link name="lidar_link">
        <inertial>
            <origin xyz="0.0 0 0.0" rpy="0 0 0"/>
            <mass value="0.125"/>
            <inertia ixx="0.001"  ixy="0"  ixz="0" iyy="0.001" iyz="0" izz="0.001" />
        </inertial>

        <visual>
            <origin xyz="0 0 0" rpy="0 0 0"/>
            <geometry>
            <cylinder radius="${0.06985/2}" length="0.0254"/>
            </geometry>
        </visual>
    </link>

    <joint name="lidar_joint" type="fixed">
        <parent link="base_link"/>
        <child link="lidar_link"/>
        <origin xyz="-0.1143 -0.1143 0.2921" rpy="0 0 0"/> <!--${67.562*d2r}-->
    </joint>
</robot>