<?xml version="1.0"?>
<robot name="ghost_15" xmlns:xacro="http://ros.org/wiki/xacro">

    <xacro:include filename="$(find ghost_swerve)/urdf/swerve_v2_macros.xacro"/>

    <xacro:property name="d2r" value="${3.14159/180}"/>
    <xacro:property name="in2m" value="${0.0254}"/>
    <xacro:property name="r_wheel" value="${1.375*in2m}"/> 
    <xacro:property name="width_wheel" value="${1.0*in2m}"/> 
    <xacro:property name="com_radius" value="0.02"/>

    <xacro:property name="module_vertical_offset" value="${2.75*in2m}"/>
    <xacro:property name="module_to_wheel_vertical_offset" value="${3.907*in2m}"/>
    <xacro:property name="module_horizontal_offset" value="${12.5*in2m/2.0}"/>

    <link name="base_link">
        <visual>
        <origin xyz="0 0 0" rpy="0 0 0"/>
        <geometry>
            <box size="0 0 0"/>
        </geometry>
            <material name="silver">
                <color rgba="0.9 0.9 0.9 1.0"/>
            </material>
        </visual>

        <!--Inertia estimated for solid cylinder of radius 9" and height 3" with mass 7kg-->
        <inertial>
            <origin xyz="0 0 0" rpy="0 0 0"/>
            <mass value="10"/>
            <inertia
                ixx="0.094839" ixy="0.0" ixz="0.0"
                iyy="0.094839" iyz="0.0"
                izz="0.182903"/>
        </inertial>

        <gazebo>
            <maxVel>3.0</maxVel>
        </gazebo>
    </link>

    <link name="base_footprint">
        <origin xyz="0 0 0" rpy="0 0 0"/>
    </link>    

    <joint name="base_footprint_joint" type="fixed">
        <parent link="base_link"/>
        <child link="base_footprint"/>
        <origin xyz="0 0 -${2.4375*in2m}" rpy="0 0 0"/>
        <axis xyz="0 0 1"/>
    </joint>

    <link name="front_bar">
        <visual>
        <origin xyz="0 0 0" rpy="0 0 0"/>
        <geometry>
            <box size="${0.5*in2m} ${16.5*in2m} ${1.0*in2m}"/>
        </geometry>
            <material name="silver">
                <color rgba="0.9 0.9 0.9 1.0"/>
            </material>
        </visual>
    </link>    

    <joint name="front_bar_joint" type="fixed">
        <parent link="base_link"/>
        <child link="front_bar"/>
        <origin xyz="${8.0*in2m} 0 0" rpy="0 0 0"/>
        <axis xyz="0 0 1"/>
    </joint>

    <link name="back_bar">
        <visual>
        <origin xyz="0 0 0" rpy="0 0 0"/>
        <geometry>
            <box size="${0.5*in2m} ${16.5*in2m} ${1.0*in2m}"/>
        </geometry>
            <material name="silver">
                <color rgba="0.9 0.9 0.9 1.0"/>
            </material>
        </visual>
    </link>    

    <joint name="back_bar_joint" type="fixed">
        <parent link="base_link"/>
        <child link="back_bar"/>
        <origin xyz="-${8.0*in2m} 0 0" rpy="0 0 0"/>
        <axis xyz="0 0 1"/>
    </joint>

    <link name="left_bar">
        <visual>
        <origin xyz="0 0 0" rpy="0 0 0"/>
        <geometry>
            <box size="${0.5*in2m} ${16.5*in2m} ${1.0*in2m}"/>
        </geometry>
            <material name="silver">
                <color rgba="0.9 0.9 0.9 1.0"/>
            </material>
        </visual>
    </link>

    <joint name="left_bar_joint" type="fixed">
        <parent link="base_link"/>
        <child link="left_bar"/>
        <origin xyz="0 ${8.0*in2m} 0" rpy="0 0 ${90.0*d2r}"/>
        <axis xyz="0 0 1"/>
    </joint>

    <link name="right_bar">
        <visual>
        <origin xyz="0 0 0" rpy="0 0 0"/>
        <geometry>
            <box size="${0.5*in2m} ${16.5*in2m} ${1.0*in2m}"/>
        </geometry>
            <material name="silver">
                <color rgba="0.9 0.9 0.9 1.0"/>
            </material>
    </visual>
    </link>

    <joint name="right_bar_joint" type="fixed">
        <parent link="base_link"/>
        <child link="right_bar"/>
        <origin xyz="0 -${8.0*in2m} 0" rpy="0 0 ${90.0*d2r}"/>
        <axis xyz="0 0 1"/>
    </joint>

    <!-- Steering Modules -->
    <xacro:steering_macro id="front_left"></xacro:steering_macro>
    <xacro:steering_macro id="front_right"></xacro:steering_macro>
    <xacro:steering_macro id="back_left"></xacro:steering_macro>
    <xacro:steering_macro id="back_right"></xacro:steering_macro>

    <!-- Wheel Modules -->
    <xacro:wheel_macro id="front_left" r_wheel="${r_wheel}" width_wheel="${width_wheel}" collision_factor="8"></xacro:wheel_macro>
    <xacro:wheel_macro id="front_right" r_wheel="${r_wheel}" width_wheel="${width_wheel}" collision_factor="8"></xacro:wheel_macro>
    <xacro:wheel_macro id="back_left" r_wheel="${r_wheel}" width_wheel="${width_wheel}" collision_factor="8"></xacro:wheel_macro>
    <xacro:wheel_macro id="back_right" r_wheel="${r_wheel}" width_wheel="${width_wheel}" collision_factor="8"></xacro:wheel_macro>
    <!-- Joints -->
    <joint name="steering_joint_back_left" type="continuous">
        <parent link="base_link"/>
        <child link="steering_link_back_left"/>
        <origin xyz="-${module_horizontal_offset} ${module_horizontal_offset} ${module_vertical_offset}" rpy="0 0 0"/> 
        <dynamics damping="0.0" friction="0.0"/>
        <axis xyz="0 0 1"/>
    </joint>

    <joint name="steering_joint_back_right" type="continuous">
        <parent link="base_link"/>
        <child link="steering_link_back_right"/>
        <origin xyz="-${module_horizontal_offset} -${module_horizontal_offset} ${module_vertical_offset}" rpy="0 0 0"/>
        <dynamics damping="0.0" friction="0.0"/>
        <axis xyz="0 0 1"/>
    </joint>

    <joint name="steering_joint_front_left" type="continuous">
        <parent link="base_link"/>
        <child link="steering_link_front_left"/>
        <origin xyz="${module_horizontal_offset} ${module_horizontal_offset} ${module_vertical_offset}" rpy="0 0 0"/>
        <dynamics damping="0.0" friction="0.0"/>
        <axis xyz="0 0 1"/>
    </joint>

    <joint name="steering_joint_front_right" type="continuous">
        <parent link="base_link"/>
        <child link="steering_link_front_right"/>
        <origin xyz="${module_horizontal_offset} -${module_horizontal_offset} ${module_vertical_offset} " rpy="0 0 0"/> 
        <dynamics damping="0.0" friction="0.0"/>
        <axis xyz="0 0 1"/>
    </joint>

    <joint name="wheel_joint_back_left" type="continuous">
        <parent link="steering_link_back_left"/>
        <child link="wheel_link_back_left"/>
        <origin xyz="0 0 -${module_to_wheel_vertical_offset}" rpy="${-90*d2r} 0 0"/> 
        <dynamics damping="0.0" friction="0.0"/>
        <axis xyz="0 0 1"/>
    </joint>

    <joint name="wheel_joint_back_right" type="continuous">
        <parent link="steering_link_back_right"/>
        <child link="wheel_link_back_right"/>
        <origin xyz="0 0 -${module_to_wheel_vertical_offset}" rpy="${-90*d2r} 0 0"/>
        <dynamics damping="0.0" friction="0.0"/>
        <axis xyz="0 0 1"/>
    </joint>

    <joint name="wheel_joint_front_left" type="continuous">
        <parent link="steering_link_front_left"/>
        <child link="wheel_link_front_left"/>
        <origin xyz="0 0 -${module_to_wheel_vertical_offset}" rpy="${-90*d2r} 0 0"/>
        <dynamics damping="0.0" friction="0.0"/>
        <axis xyz="0 0 1"/>
    </joint>

    <joint name="wheel_joint_front_right" type="continuous">
        <parent link="steering_link_front_right"/>
        <child link="wheel_link_front_right"/>
        <origin xyz="0 0 -${module_to_wheel_vertical_offset}" rpy="${-90*d2r} 0 0"/>
        <dynamics damping="0.0" friction="0.0"/>
        <axis xyz="0 0 1"/>
    </joint>

    <!-- Gears :) 
     <link name="gear_backleft">
        <visual>
        <origin xyz="0 0 0" rpy="0 0 0"/>
        <geometry>
           <cylinder radius="0.04826" length="0.0127"/>
        </geometry>
            <material name="orange">
                <color rgba="1.0 0.5 0.0 1.0"/>
            </material>
        </visual>
    </link>

     <joint name="steering_gear_backleft" type="continuous">
        <parent link="steering_link_backleft"/>
        <child link="gear_backleft"/>
        <origin xyz="0 0 -0.0508" rpy="0 0 0"/> 
        <dynamics damping="0.0" friction="0.0"/>
        <axis xyz="0 0 1"/>
    </joint>

    

     <link name="gear_backright">
        <visual>
        <origin xyz="0 0 0" rpy="0 0 0"/>
        <geometry>
           <cylinder radius="0.04826" length="0.0127"/>
        </geometry>
            <material name="orange">
                <color rgba="1.0 0.5 0.0 1.0"/>
            </material>
        </visual>
    </link>

     <joint name="steering_gear_backright" type="continuous">
        <parent link="steering_link_backright"/>
        <child link="gear_backright"/>
        <origin xyz="0 0 -0.0508" rpy="0 0 0"/> 
        <dynamics damping="0.0" friction="0.0"/>
        <axis xyz="0 0 1"/>
    </joint>

     <link name="gear_frontleft">
        <visual>
        <origin xyz="0 0 0" rpy="0 0 0"/>
        <geometry>
           <cylinder radius="0.04826" length="0.0127"/>
        </geometry>
            <material name="orange">
                <color rgba="1.0 0.5 0.0 1.0"/>
            </material>
        </visual>
    </link>

     <joint name="steering_gear_frontleft" type="continuous">
        <parent link="steering_link_frontleft"/>
        <child link="gear_frontleft"/>
        <origin xyz="0 0 -0.0508" rpy="0 0 0"/> 
        <dynamics damping="0.0" friction="0.0"/>
        <axis xyz="0 0 1"/>
    </joint>

<link name="gear_frontright">
        <visual>
        <origin xyz="0 0 0" rpy="0 0 0"/>
        <geometry>
           <cylinder radius="0.04826" length="0.0127"/>
        </geometry>
            <material name="orange">
                <color rgba="1.0 0.5 0.0 1.0"/>
            </material>
        </visual>
    </link>

     <joint name="steering_gear_frontright" type="continuous">
        <parent link="steering_link_frontright"/>
        <child link="gear_frontright"/>
        <origin xyz="0 0 -0.0508" rpy="0 0 0"/> 
        <dynamics damping="0.0" friction="0.0"/>
        <axis xyz="0 0 1"/>
    </joint>-->


    <!-- Sensors -->
    <link name="lidar_link">
        <inertial>
            <origin xyz="0.0 0 0.0" rpy="0 0 0"/>
            <mass value="0.125"/>
            <inertia ixx="0.001"  ixy="0"  ixz="0" iyy="0.001" iyz="0" izz="0.001" />
        </inertial>

        <visual>
            <origin xyz="0 0 0" rpy="0 0 0"/>
            <geometry>
            <cylinder radius="${0.06985/2}" length="0.0254"/>
            </geometry>
        </visual>
    </link>

    <joint name="lidar_joint" type="fixed">
        <parent link="base_link"/>
        <child link="lidar_link"/>
        <origin xyz="${6.25*in2m} -${6.25*in2m} ${8*in2m}" rpy="0 0 ${90.0*d2r}"/>
    </joint>
</robot>